Workbook
Name AcquaComp: '02_1_TAM_SAM_SOM_Agricolo'!#REF!
Name ARPU: [1]Assumptions!$C$4
Name CAC: [1]Assumptions!$C$7
Name ChurnRate: [1]Assumptions!$C$6
Name ClientServiceCost: [1]Assumptions!$C$8
Name EBITDA1: '[1]P&L'!$C$10
Name EBITDA2: '[1]P&L'!$D$10
Name EBITDA3: '[1]P&L'!$E$10
Name FixedCostsAnnual: [1]Assumptions!$C$9
Name GrowthYoY: [1]Assumptions!$C$5
Name LargeLivestockComp: '02_1_TAM_SAM_SOM_Agricolo'!#REF!
Name LTV: '[1]Unit Economics'!$C$5
Name MidLivestockComp: '02_1_TAM_SAM_SOM_Agricolo'!#REF!
Name PetComp: '02_1_TAM_SAM_SOM_Agricolo'!#REF!
Name SAMAcquaComp: '02_1_TAM_SAM_SOM_Agricolo'!#REF!
Name SAMLargeLivestockComp: '02_1_TAM_SAM_SOM_Agricolo'!#REF!
Name SAMMidLivestockComp: '02_1_TAM_SAM_SOM_Agricolo'!#REF!
Name SAMPetComp: '02_1_TAM_SAM_SOM_Agricolo'!#REF!
Name TAMAcqua: '02_1_TAM_SAM_SOM_Agricolo'!$E$11:$E$11
Name TAMLivestock: '02_1_TAM_SAM_SOM_Agricolo'!$C$11:$C$11
Name TAMPet: '02_1_TAM_SAM_SOM_Agricolo'!#REF!

Sheet 00_Index
A1: ReSemis Financial Model - Navigation
A3: Sheet Name | B3: Description
A4: 00_Index | B4: This navigation sheet
A5: 01_Executive_Summary | B5: Key metrics and highlights
A6: 02_TAM_SAM_SOM | B6: Market sizing (from Integrated model)
A7: 03_Product_Lines | B7: Product roadmap by year
A8: 04_Assumptions | B8: All manual input assumptions
A9: 05_Revenue_Model | B9: Customer counts and revenue build-up
A10: 06_COGS | B10: Cost of goods sold details
A11: 07_OpEx | B11: Operating expenses
A12: 08_P&L | B12: Profit & Loss statement
A13: 09_Cash_Flow | B13: Cash flow statement with funding rounds
A14: 10_KPIs | B14: Key performance indicators
... A17: 13_Sensitivity | B17: Sensitivity analysis

Sheet 01_Executive_Summary
A1: ReSemis - Executive Summary
A3: Investment Highlights
A4: Addressable Market (Italy) | B4: €20-66M TAM | C4: Poultry sector focus
A5: Target 2028 Revenue | B5: €1.8-2.5M | C5: Base case conservative scenario
A6: Gross Margin Target | B6: 45-55% | C6: Sustainable unit economics
A7: Capital Efficiency | B7: High | C7: Externalized production
A9: Key Financial Metrics
A10: Metric | B10: 2026 | C10: 2027 | D10: 2028 | E10: 2029 | F10: 2030
A11: Revenue (€) | B11: ='08_P&L'!B5 -> 0 | C11: ='08_P&L'!C5 -> 61354 | D11: ='08_P&L'!D5 -> 839676.8 | E11: ='08_P&L'!E5 -> 3052923.9 | F11: ='08_P&L'!F5 -> 7023199.5
A12: Gross Profit (€) | B12: ='08_P&L'!B7 -> 0 | C12: ='08_P&L'!C7 -> 37115.423 | D12: ='08_P&L'!D7 -> 406111.43 | E12: ='08_P&L'!E7 -> 1715761.8 | F12: ='08_P&L'!F7 -> 4270691.4
A13: Gross Margin % | B13: ='08_P&L'!B8 -> 0 | C13: ='08_P&L'!C8 -> 0.60493893 | D13: ='08_P&L'!D8 -> 0.48365208 | E13: ='08_P&L'!E8 -> 0.56200607 | F13: ='08_P&L'!F8 -> 0.60808345
A14: EBITDA (€) | B14: ='08_P&L'!B17 -> -200000 | C14: ='08_P&L'!C17 -> -562884.58 | D14: ='08_P&L'!D17 -> -393888.57 | E14: ='08_P&L'!E17 -> 755761.76 | F14: ='08_P&L'!F17 -> 3140691.4
A15: EBITDA Margin % | B15: ='08_P&L'!B18 -> 0 | C15: ='08_P&L'!C18 -> -9.1743746 | D15: ='08_P&L'!D18 -> -0.46909546 | E15: ='08_P&L'!E18 -> 0.24755342 | F15: ='08_P&L'!F18 -> 0.44718812
A17: Customers (#) | B17: ='05_Revenue_Model'!B30 -> 10 | C17: ='05_Revenue_Model'!C30 -> 99.2 | D17: ='05_Revenue_Model'!D30 -> 529.28 | E17: ='05_Revenue_Model'!E30 -> 1196.352 | F17: ='05_Revenue_Model'!F30 -> 2002.7898
A18: Kg Sold | B18: ='06_COGS'!B8 -> 0 | C18: ='06_COGS'!C8 -> 3552 | D18: ='06_COGS'!D8 -> 22795.2 | E18: ='06_COGS'!E8 -> 69354.24 | F18: ='06_COGS'!F8 -> 151289.66
A20: Funding Rounds
A21: Round | B21: Amount | C21: Pre-Money | D21: Equity %
A22: 2026 Seed | B22: ='11_Funding'!C4 -> 200000 | C22: ='11_Funding'!D4 -> 2000000 | D22: =B22/(B22+C22) -> 0.090909091
A23: 2027 Pre-A | B23: ='11_Funding'!C5 -> 1500000 | C23: ='11_Funding'!D5 -> 7000000 | D23: =B23/(B23+C23) -> 0.17647059
A24: 2028 Series A | B24: ='11_Funding'!C6 -> 4000000 | C24: ='11_Funding'!D6 -> 14000000 | D24: =B24/(B24+C24) -> 0.22222222

Sheet 02_TAM_SAM_SOM_Poultry
A1: Total Addressable Market - Italy Poultry Sector
A3: Market Segment | B3: RunCover Ovaiole | C3: RunCover Broiler | D3: LitterCover | E3: TOTAL
A4: Data Source | B4: ResearchGate (2020) | C4: BCC EU Report | D4: Industry estimates
A6: Italian poultry meat production tons/year | C6: 1060000
A7: Average animal weight (kg) | C7: 1.7
A8: Average animal litter (kg/year) | B8: =C8*C12 -> 13 | C8: 2
A10: Total animals / volume (Italy) | B10: 43000000 | C10: =C6*1000/C7 -> 6.2352941e+08 | D10: =((B10*B8)+(C10*C8))/1000 -> 1806058.8
A11: Unit | B11: hens/year | C11: broilers/year | D11: tons/year
A12: Average cycles per year | B12: 1 | C12: 6.5
A13: Continuous production units | B13: =B10/B12 -> 43000000 | C13: =C10/C12 -> 95927602
A15: Avg feed per unit (kg/year) | B15: 40 | C15: 40
A16: Total feed consumption (kg/year) | B16: =B13*B15 -> 1720000000 | C16: =C15*C13 -> 3.8371041e+09
A18: ReSemis Inclusion % | B18: 0.01 | C18: 0.01 | D18: 0.01
A19: ReSemis kg/year (TAM volume) | B19: =B18*B16 -> 17200000 | C19: =C18*C16 -> 38371041 | D19: =D18*D10*1000 -> 18060588
A21: Price per kg (€) - low | B21: 8 | C21: 8 | D21: 5
A22: Price per kg (€) - mid | B22: 9 | C22: 9 | D22: 7
A23: Price per kg (€) - high | B23: 10 | C23: 10 | D23: 9
A25: TAM (€, low) | B25: =B19*B21 -> 137600000 | C25: =C19*C21 -> 3.0696833e+08 | D25: =D19*D21 -> 90302941 | E25: =SUM(B25:D25) -> 5.3487127e+08
A26: TAM (€, mid) | B26: =B19*B22 -> 154800000 | C26: =C19*C22 -> 3.4533937e+08 | D26: =D19*D22 -> 1.2642412e+08 | E26: =SUM(B26:D26) -> 6.2656348e+08
A27: TAM (€, high) | B27: =B19*B23 -> 172000000 | C27: =C19*C23 -> 3.8371041e+08 | D27: =D19*D23 -> 1.6254529e+08 | E27: =SUM(B27:D27) -> 7.182557e+08
A29: % Addressable (SAM %) | B29: 0.1 | C29: 0.2 | D29: 0.2
A30: SAM (€, low) | B30: =B25*B29 -> 13760000 | C30: =C25*C29 -> 61393665 | D30: =D25*D29 -> 18060588 | E30: =SUM(B30:D30) -> 93214253
A31: SAM (€, mid) | B31: =B26*B29 -> 15480000 | C31: =C26*C29 -> 69067873 | D31: =D26*D29 -> 25284824 | E31: =SUM(B31:D31) -> 1.098327e+08
A32: SAM (€, high) | B32: =B27*B29 -> 17200000 | C32: =C27*C29 -> 76742081 | D32: =D27*D29 -> 32509059 | E32: =SUM(B32:D32) -> 1.2645114e+08
A34: Market Penetration (SOM %) | B34: 0.05 | C34: 0.05 | D34: 0.05
A35: SOM (€, low) | B35: =B30*B34 -> 688000 | C35: =C30*C34 -> 3069683.3 | D35: =D30*D34 -> 903029.41 | E35: =SUM(B35:D35) -> 4660712.7
A36: SOM (€, mid) | B36: =B31*B34 -> 774000 | C36: =C31*C34 -> 3453393.7 | D36: =D31*D34 -> 1264241.2 | E36: =SUM(B36:D36) -> 5491634.8
A37: SOM (€, high) | B37: =B32*B34 -> 860000 | C37: =C32*C34 -> 3837104.1 | D37: =D32*D34 -> 1625452.9 | E37: =SUM(B37:D37) -> 6322557

Sheet 02_1_TAM_SAM_SOM_Agricolo
B2: Modello B2B per account | C2: Livestock - Large | D2: Livestock - Mid | E2: Acquaculture | F2: Pet | G2: TOTAL | I2: Tabella di conversione per Animali Equivalenti
B3: Average Equivalent Animals per customer | C3: 8000 | D3: 2500 | E3: - | F3: - | G3: - | I3: Specie | J3: Mangime annuo | K3: Animali equivalenti
B4: Consumption kg | C4: 50 | D4: 50 | E4: 50000 | F4: 300000 | G4: - | I4: Pollo | J4: 50 kg | K4: 1
B5: Inclusion % (Resemis per kg Consumed) | C5: 0.01 | D5: 0.01 | E5: 0.02 | F5: 0.01 | G5: - | I5: Suino | J5: 300 kg | K5: 6
B6: Avg order size Resemis kg/Year | C6: =C3*C4*C5 -> 4000 | D6: =D3*D4*D5 -> 1250 | E6: =E4*E5 -> 1000 | F6: =F4*F5 -> 3000 | G6: - | I6: Bovino | J6: 3.000 kg | K6: 60
B7: Avg unit price €/kg | C7: 10 | D7: 10 | E7: 12 | F7: 15 | G7: - | I7: Pesce allevamento | J7: 25 kg | K7: 0.5
B8: Avg annual revenue per customer (€) | C8: =C7*C6 -> 40000 | D8: =D7*D6 -> 12500 | E8: =E7*E6 -> 12000 | F8: =F7*F6 -> 45000 | G8: -
B10: Total units / volume Italy | C10: https://www.cia.it/news/notizie/censimento-istat-meno-aziende-agricole-ma-piu-grandi-e-sempre-familiari/?utm_source=chatgpt.com | E10: https://www.fao.org/fishery/es/countrysector/it/en?utm_source=chatgpt.com | F10: https://www.zoomark.it/media/zoomark/pressrelease/2025/comunicati%20stampa/Assalco_-_Zoomark_Report_2025_-_Summary.pdf?utm_source=chatgpt.com
B11: Total farms in target geography (TAM) | C11: 213984 | E11: 820 | F11: 500 | G11: =SUM(C11:F11) -> 215304
B12: TAM (€) | C12: =C$8*C11 -> 8559360000 | E12: =E$8*E11 -> 9840000 | F12: =F$8*F11 -> 22500000 | G12: =SUM(C12:F12) -> 8591700000
B14: % addressable with current product (SAM %) | C14: 0.2 | D14: 0.3 | E14: 1 | F14: 0.8 | G14: -
B15: Serviceable customers (SAM) | C15: =C11*C14 -> 42796.8 | D15: =C11*D14 -> 64195.2 | E15: =E11*E14 -> 820 | F15: =F11*F14 -> 400 | G15: =SUM(C15:F15) -> 108212
B16: SAM (€) | C16: =C$8*C15 -> 1711872000 | D16: =D$8*D15 -> 802440000 | E16: =E$8*E15 -> 9840000 | F16: =F$8*F15 -> 18000000 | G16: =SUM(C16:F16) -> 2542152000
B18: Expected market penetration (SOM %) | C18: 0.05 | D18: 0.05 | E18: 0.05 | F18: 0.05 | G18: -
B19: Target customers (SOM) | C19: =C18*C15 -> 2139.84 | D19: =D18*D15 -> 3209.76 | E19: =E18*E15 -> 41 | F19: =F18*F15 -> 20 | G19: =SUM(C19:F19) -> 5410.6
B20: SOM (€) | C20: =C$8*C19 -> 85593600 | D20: =D$8*D19 -> 40122000 | E20: =E$8*E19 -> 492000 | F20: =F$8*F19 -> 900000 | G20: =SUM(C20:F20) -> 127107600

Sheet 03_Product_Lines
A1: Product Line Roadmap
A3: 2026 - Validation Phase
A4: • Focus: R&D, validation, hub light, patent (PCT)
A5: • Revenue: Minimal (€0-20k from subsidized pilots)
A9: 2027 - Soft Launch
A10: • Focus: First paid customers, unit economics validation
A11: • Revenue: €150k-300k
A12: • Customers: 30-60 early adopters
A13: • Products: RunCover Ovaiole v1.0, RunCover Broiler v1.0, LitterCover v1.0
A14: • Pricing: Discounted for early feedback
A16: 2028 - Commercial Launch
A17: • Focus: Full commercial launch through 4-6 partners
... A28: • Efficiency: COGS reduction through scale, improved processes

Sheet 04_Assumptions
A1: ReSemis Financial Model - Core Assumptions
A2: All values in BLUE are manual inputs - adjust these to model different scenarios
A4: Assumption | B4: 2026 | C4: 2027 | D4: 2028 | E4: 2029 | F4: 2030
A6: PRICING
A7: RunCover Ovaiole (€/customer/year) | B7: 0 | C7: 600 | D7: 800 | E7: 900 | F7: 1000
A8: RunCover Broiler (€/customer/year) | B8: 0 | C8: 150 | D8: 200 | E8: 250 | F8: 300
A9: LitterCover (€/partner/year) | B9: 0 | C9: 2000 | D9: 3000 | E9: 4000 | F9: 5000
A11: CUSTOMER ACQUISITION
A12: New Ovaiole customers | B12: 5 | C12: 50 | D12: 250 | E12: 400 | F12: 500
A13: New Broiler customers | B13: 3 | C13: 30 | D13: 150 | E13: 250 | F13: 350
A14: New LitterCover partners | B14: 2 | C14: 10 | D14: 40 | E14: 70 | F14: 100
A15: Annual churn rate | B15: 0 | C15: 0.08 | D15: 0.1 | E15: 0.1 | F15: 0.12
A17: COSTS
A18: COGS per kg (€) | B18: ='14_Unit_Costs_BOM'!$D$37 -> 3.494 | C18: ='14_Unit_Costs_BOM'!$D$37 -> 3.494 | D18: ='14_Unit_Costs_BOM'!$D$37*0.95 -> 3.3193 | E18: ='14_Unit_Costs_BOM'!$D$37*0.9 -> 3.1446 | F18: ='14_Unit_Costs_BOM'!$D$37*0.85 -> 2.9699
A19: Kg per Ovaiole customer | B19: 0 | C19: 50 | D19: 70 | E19: 85 | F19: 100
A20: Kg per Broiler customer | B20: 0 | C20: 20 | D20: 30 | E20: 40 | F20: 50
A21: Kg per LitterCover partner | B21: 0 | C21: 300 | D21: 450 | E21: 600 | F21: 750
A23: OPERATING EXPENSES
A24: Team & Salaries (€) | B24: 100000 | C24: 300000 | D24: 400000 | E24: 500000 | F24: 600000
A25: R&D & Validation (€) | B25: 50000 | C25: 100000 | D25: 80000 | E25: 60000 | F25: 50000
A26: Marketing & Sales (€) | B26: 20000 | C26: 120000 | D26: 200000 | E26: 250000 | F26: 300000
A27: General & Admin (€) | B27: 30000 | C27: 80000 | D27: 120000 | E27: 150000 | F27: 180000
A29: FUNDING ROUNDS
A30: Capital Raised (€) | B30: 200000 | C30: 1500000 | D30: 4000000 | E30: 0 | F30: 0
A31: Pre-money Valuation (€) | B31: 2000000 | C31: 7000000 | D31: 14000000 | E31: 0 | F31: 0
A32: SEGMENTI AGRICOLI AGGIUNTIVI (da 02_1_TAM_SAM_SOM_Agricolo)
A33: Note: questi segmenti sono attivati progressivamente dal 2028
A35: Livestock Large (bovini, suini grandi)
A36: New customers | B36: 0 | C36: 0 | D36: 15 | E36: 35 | F36: 60
A37: Avg revenue per customer (€/year) | B37: 0 | C37: 0 | D37: 35000 | E37: 38000 | F37: 40000
A38: Kg per customer | B38: 0 | C38: 0 | D38: 3500 | E38: 3800 | F38: 4000
A40: Livestock Mid (ovini, caprini, suini medi)
A41: New customers | B41: 0 | C41: 0 | D41: 25 | E41: 50 | F41: 80
A42: Avg revenue per customer (€/year) | B42: 0 | C42: 0 | D42: 10000 | E42: 11500 | F42: 12500
A43: Kg per customer | B43: 0 | C43: 0 | D43: 1000 | E43: 1150 | F43: 1250
A45: Acquaculture (orate, branzini)
A46: New customers | B46: 0 | C46: 0 | D46: 5 | E46: 12 | F46: 20
A47: Avg revenue per customer (€/year) | B47: 0 | C47: 0 | D47: 10000 | E47: 11000 | F47: 12000
A48: Kg per customer | B48: 0 | C48: 0 | D48: 800 | E48: 900 | F48: 1000
A50: Churn rate segmenti agricoli | B50: 0 | C50: 0 | D50: 0.08 | E50: 0.1 | F50: 0.1

Sheet 05_Revenue_Model
A1: Revenue Build-Up Model
A3: Metric | B3: 2026 | C3: 2027 | D3: 2028 | E3: 2029 | F3: 2030
A5: RunCover Ovaiole
A6: Beginning customers | B6: 0 | C6: =B9 -> 5 | D6: =C9 -> 54.6 | E6: =D9 -> 299.14 | F6: =E9 -> 669.226
A7: New customers | B7: ='04_Assumptions'!B12 -> 5 | C7: ='04_Assumptions'!C12 -> 50 | D7: ='04_Assumptions'!D12 -> 250 | E7: ='04_Assumptions'!E12 -> 400 | F7: ='04_Assumptions'!F12 -> 500
A8: Churned customers | B8: =B6*'04_Assumptions'!B15 -> 0 | C8: =C6*'04_Assumptions'!C15 -> 0.4 | D8: =D6*'04_Assumptions'!D15 -> 5.46 | E8: =E6*'04_Assumptions'!E15 -> 29.914 | F8: =F6*'04_Assumptions'!F15 -> 80.30712
A9: Ending customers | B9: =B6+B7-B8 -> 5 | C9: =C6+C7-C8 -> 54.6 | D9: =D6+D7-D8 -> 299.14 | E9: =E6+E7-E8 -> 669.226 | F9: =F6+F7-F8 -> 1088.9189
A10: Avg revenue per customer (€) | B10: ='04_Assumptions'!B7 -> 0 | C10: ='04_Assumptions'!C7 -> 600 | D10: ='04_Assumptions'!D7 -> 800 | E10: ='04_Assumptions'!E7 -> 900 | F10: ='04_Assumptions'!F7 -> 1000
A11: Revenue (€) | B11: =B9*B10 -> 0 | C11: =C9*C10 -> 32760 | D11: =D9*D10 -> 239312 | E11: =E9*E10 -> 602303.4 | F11: =F9*F10 -> 1088918.9
A13: RunCover Broiler
A14: Beginning customers | B14: 0 | C14: =B17 -> 3 | D14: =C17 -> 32.76 | E14: =D17 -> 179.484 | F14: =E17 -> 411.5356
A15: New customers | B15: ='04_Assumptions'!B13 -> 3 | C15: ='04_Assumptions'!C13 -> 30 | D15: ='04_Assumptions'!D13 -> 150 | E15: ='04_Assumptions'!E13 -> 250 | F15: ='04_Assumptions'!F13 -> 350
A16: Churned customers | B16: =B14*'04_Assumptions'!B15 -> 0 | C16: =C14*'04_Assumptions'!C15 -> 0.24 | D16: =D14*'04_Assumptions'!D15 -> 3.276 | E16: =E14*'04_Assumptions'!E15 -> 17.9484 | F16: =F14*'04_Assumptions'!F15 -> 49.384272
A17: Ending customers | B17: =B14+B15-B16 -> 3 | C17: =C14+C15-C16 -> 32.76 | D17: =D14+D15-D16 -> 179.484 | E17: =E14+E15-E16 -> 411.5356 | F17: =F14+F15-F16 -> 712.15133
A18: Avg revenue per customer (€) | B18: ='04_Assumptions'!B8 -> 0 | C18: ='04_Assumptions'!C8 -> 150 | D18: ='04_Assumptions'!D8 -> 200 | E18: ='04_Assumptions'!E8 -> 250 | F18: ='04_Assumptions'!F8 -> 300
A19: Revenue (€) | B19: =B17*B18 -> 0 | C19: =C17*C18 -> 4914 | D19: =D17*D18 -> 35896.8 | E19: =E17*E18 -> 102883.9 | F19: =F17*F18 -> 213645.4
A21: LitterCover
A22: Beginning partners | B22: 0 | C22: =B25 -> 2 | D22: =C25 -> 11.84 | E22: =D25 -> 50.656 | F22: =E25 -> 115.5904
A23: New partners | B23: ='04_Assumptions'!B14 -> 2 | C23: ='04_Assumptions'!C14 -> 10 | D23: ='04_Assumptions'!D14 -> 40 | E23: ='04_Assumptions'!E14 -> 70 | F23: ='04_Assumptions'!F14 -> 100
A24: Churned partners | B24: =B22*'04_Assumptions'!B15 -> 0 | C24: =C22*'04_Assumptions'!C15 -> 0.16 | D24: =D22*'04_Assumptions'!D15 -> 1.184 | E24: =E22*'04_Assumptions'!E15 -> 5.0656 | F24: =F22*'04_Assumptions'!F15 -> 13.870848
A25: Ending partners | B25: =B22+B23-B24 -> 2 | C25: =C22+C23-C24 -> 11.84 | D25: =D22+D23-D24 -> 50.656 | E25: =E22+E23-E24 -> 115.5904 | F25: =F22+F23-F24 -> 201.71955
A26: Avg revenue per partner (€) | B26: ='04_Assumptions'!B9 -> 0 | C26: ='04_Assumptions'!C9 -> 2000 | D26: ='04_Assumptions'!D9 -> 3000 | E26: ='04_Assumptions'!E9 -> 4000 | F26: ='04_Assumptions'!F9 -> 5000
A27: Revenue (€) | B27: =B25*B26 -> 0 | C27: =C25*C26 -> 23680 | D27: =D25*D26 -> 151968 | E27: =E25*E26 -> 462361.6 | F27: =F25*F26 -> 1008597.8
A29: TOTAL REVENUE (€) | B29: =B11+B19+B27 -> 0 | C29: =C11+C19+C27 -> 61354 | D29: =D11+D19+D27 -> 427176.8 | E29: =E11+E19+E27 -> 1167548.9 | F29: =F11+F19+F27 -> 2311162
A30: Total customers | B30: =B9+B17+B25 -> 10 | C30: =C9+C17+C25 -> 99.2 | D30: =D9+D17+D25 -> 529.28 | E30: =E9+E17+E25 -> 1196.352 | F30: =F9+F17+F25 -> 2002.7898
A31: SEGMENTI AGRICOLI AGGIUNTIVI
A33: Livestock Large
A34: Beginning customers | B34: 0 | C34: =B37 -> 0 | D34: =C37 -> 0 | E34: =D37 -> 15 | F34: =E37 -> 48.5
A35: New customers | B35: ='04_Assumptions'!B36 -> 0 | C35: ='04_Assumptions'!C36 -> 0 | D35: ='04_Assumptions'!D36 -> 15 | E35: ='04_Assumptions'!E36 -> 35 | F35: ='04_Assumptions'!F36 -> 60
A36: Churned customers | B36: =B34*'04_Assumptions'!B50 -> 0 | C36: =C34*'04_Assumptions'!C50 -> 0 | D36: =D34*'04_Assumptions'!D50 -> 0 | E36: =E34*'04_Assumptions'!E50 -> 1.5 | F36: =F34*'04_Assumptions'!F50 -> 4.85
A37: Ending customers | B37: =B34+B35-B36 -> 0 | C37: =C34+C35-C36 -> 0 | D37: =D34+D35-D36 -> 15 | E37: =E34+E35-E36 -> 48.5 | F37: =F34+F35-F36 -> 103.65
A38: Avg revenue per customer (€) | B38: ='04_Assumptions'!B37 -> 0 | C38: ='04_Assumptions'!C37 -> 0 | D38: ='04_Assumptions'!D37 -> 35000 | E38: ='04_Assumptions'!E37 -> 38000 | F38: ='04_Assumptions'!F37 -> 40000
A39: Revenue (€) | B39: =(B34+B37)/2*B38 -> 0 | C39: =(C34+C37)/2*C38 -> 0 | D39: =(D34+D37)/2*D38 -> 262500 | E39: =(E34+E37)/2*E38 -> 1206500 | F39: =(F34+F37)/2*F38 -> 3043000
A41: Livestock Mid
A42: Beginning customers | B42: 0 | C42: =B45 -> 0 | D42: =C45 -> 0 | E42: =D45 -> 25 | F42: =E45 -> 72.5
A43: New customers | B43: ='04_Assumptions'!B41 -> 0 | C43: ='04_Assumptions'!C41 -> 0 | D43: ='04_Assumptions'!D41 -> 25 | E43: ='04_Assumptions'!E41 -> 50 | F43: ='04_Assumptions'!F41 -> 80
A44: Churned customers | B44: =B42*'04_Assumptions'!B50 -> 0 | C44: =C42*'04_Assumptions'!C50 -> 0 | D44: =D42*'04_Assumptions'!D50 -> 0 | E44: =E42*'04_Assumptions'!E50 -> 2.5 | F44: =F42*'04_Assumptions'!F50 -> 7.25
A45: Ending customers | B45: =B42+B43-B44 -> 0 | C45: =C42+C43-C44 -> 0 | D45: =D42+D43-D44 -> 25 | E45: =E42+E43-E44 -> 72.5 | F45: =F42+F43-F44 -> 145.25
A46: Avg revenue per customer (€) | B46: ='04_Assumptions'!B42 -> 0 | C46: ='04_Assumptions'!C42 -> 0 | D46: ='04_Assumptions'!D42 -> 10000 | E46: ='04_Assumptions'!E42 -> 11500 | F46: ='04_Assumptions'!F42 -> 12500
A47: Revenue (€) | B47: =(B42+B45)/2*B46 -> 0 | C47: =(C42+C45)/2*C46 -> 0 | D47: =(D42+D45)/2*D46 -> 125000 | E47: =(E42+E45)/2*E46 -> 560625 | F47: =(F42+F45)/2*F46 -> 1360937.5
...

Sheet 06_COGS
A1: Cost of Goods Sold
A3: Component | B3: 2026 | C3: 2027 | D3: 2028 | E3: 2029 | F3: 2030
A5: POULTRY SEGMENTS | B5: ='05_Revenue_Model'!B9*'04_Assumptions'!B19 -> 0 | C5: ='05_Revenue_Model'!C9*'04_Assumptions'!C19 -> 2730 | D5: ='05_Revenue_Model'!D9*'04_Assumptions'!D19 -> 20939.8 | E5: ='05_Revenue_Model'!E9*'04_Assumptions'!E19 -> 56884.21 | F5: ='05_Revenue_Model'!F9*'04_Assumptions'!F19 -> 108891.89
A6: Kg - Ovaiole | B6: ='05_Revenue_Model'!B9*'04_Assumptions'!B19 -> 0 | C6: ='05_Revenue_Model'!C9*'04_Assumptions'!C19 -> 2730 | D6: ='05_Revenue_Model'!D9*'04_Assumptions'!D19 -> 20939.8 | E6: ='05_Revenue_Model'!E9*'04_Assumptions'!E19 -> 56884.21 | F6: ='05_Revenue_Model'!F9*'04_Assumptions'!F19 -> 108891.89
A7: Kg - Broiler | B7: ='05_Revenue_Model'!B17*'04_Assumptions'!B20 -> 0 | C7: ='05_Revenue_Model'!C17*'04_Assumptions'!C20 -> 655.2 | D7: ='05_Revenue_Model'!D17*'04_Assumptions'!D20 -> 5384.52 | E7: ='05_Revenue_Model'!E17*'04_Assumptions'!E20 -> 16461.424 | F7: ='05_Revenue_Model'!F17*'04_Assumptions'!F20 -> 35607.566
A8: Kg - LitterCover | B8: ='05_Revenue_Model'!B25*'04_Assumptions'!B21 -> 0 | C8: ='05_Revenue_Model'!C25*'04_Assumptions'!C21 -> 3552 | D8: ='05_Revenue_Model'!D25*'04_Assumptions'!D21 -> 22795.2 | E8: ='05_Revenue_Model'!E25*'04_Assumptions'!E21 -> 69354.24 | F8: ='05_Revenue_Model'!F25*'04_Assumptions'!F21 -> 151289.66
A9: Subtotal Poultry Kg | B9: =SUM(B6:B8) -> 0 | C9: =SUM(C6:C8) -> 6937.2 | D9: =SUM(D6:D8) -> 49119.52 | E9: =SUM(E6:E8) -> 142699.87 | F9: =SUM(F6:F8) -> 295789.12
A10: COGS per kg (€) | B10: ='04_Assumptions'!B18 -> 3.494 | C10: ='04_Assumptions'!C18 -> 3.494 | D10: ='04_Assumptions'!D18 -> 3.3193 | E10: ='04_Assumptions'!E18 -> 3.1446 | F10: ='04_Assumptions'!F18 -> 2.9699
A11: AGRICULTURAL SEGMENTS | B11: =B8*B10 -> 0 | C11: =C8*C10 -> 12410.688 | D11: =D8*D10 -> 75664.107 | E11: =E8*E10 -> 218091.34 | F11: =F8*F10 -> 449315.17
A12: Kg - Livestock Large | B12: ='05_Revenue_Model'!B37*'04_Assumptions'!B38 -> 0 | C12: ='05_Revenue_Model'!C37*'04_Assumptions'!C38 -> 0 | D12: ='05_Revenue_Model'!D37*'04_Assumptions'!D38 -> 52500 | E12: ='05_Revenue_Model'!E37*'04_Assumptions'!E38 -> 184300 | F12: ='05_Revenue_Model'!F37*'04_Assumptions'!F38 -> 414600
A13: Kg - Livestock Mid | B13: ='05_Revenue_Model'!B45*'04_Assumptions'!B43 -> 0 | C13: ='05_Revenue_Model'!C45*'04_Assumptions'!C43 -> 0 | D13: ='05_Revenue_Model'!D45*'04_Assumptions'!D43 -> 25000 | E13: ='05_Revenue_Model'!E45*'04_Assumptions'!E43 -> 83375 | F13: ='05_Revenue_Model'!F45*'04_Assumptions'!F43 -> 181562.5
A14: Kg - Acquaculture | B14: ='05_Revenue_Model'!B53*'04_Assumptions'!B48 -> 0 | C14: ='05_Revenue_Model'!C53*'04_Assumptions'!C48 -> 0 | D14: ='05_Revenue_Model'!D53*'04_Assumptions'!D48 -> 4000 | E14: ='05_Revenue_Model'!E53*'04_Assumptions'!E48 -> 14850 | F14: ='05_Revenue_Model'!F53*'04_Assumptions'!F48 -> 34850
A15: Subtotal Agricultural Kg | B15: =SUM(B12:B14) -> 0 | C15: =SUM(C12:C14) -> 0 | D15: =SUM(D12:D14) -> 81500 | E15: =SUM(E12:E14) -> 282525 | F15: =SUM(F12:F14) -> 631012.5
A17: TOTAL KG SOLD | B17: =B9+B15 -> 0 | C17: =C9+C15 -> 6937.2 | D17: =D9+D15 -> 130619.52 | E17: =E9+E15 -> 425224.87 | F17: =F9+F15 -> 926801.62
A19: COGS per kg (€) | B19: ='04_Assumptions'!B18 -> 3.494 | C19: ='04_Assumptions'!C18 -> 3.494 | D19: ='04_Assumptions'!D18 -> 3.3193 | E19: ='04_Assumptions'!E18 -> 3.1446 | F19: ='04_Assumptions'!F18 -> 2.9699
A20: TOTAL COGS (€) | B20: =B17*B19 -> 0 | C20: =C17*C19 -> 24238.577 | D20: =D17*D19 -> 433565.37 | E20: =E17*E19 -> 1337162.1 | F20: =F17*F19 -> 2752508.1
A22: Revenue (from Revenue Model) | B22: ='05_Revenue_Model'!B62 -> 0 | C22: ='05_Revenue_Model'!C62 -> 61354 | D22: ='05_Revenue_Model'!D62 -> 839676.8 | E22: ='05_Revenue_Model'!E62 -> 3052923.9 | F22: ='05_Revenue_Model'!F62 -> 7023199.5
A23: Gross Profit (€) | B23: =B22-B20 -> 0 | C23: =C22-C20 -> 37115.423 | D23: =D22-D20 -> 406111.43 | E23: =E22-E20 -> 1715761.8 | F23: =F22-F20 -> 4270691.4
A24: Gross Margin % | B24: =IF(B22=0,0,B23/B22) -> 0 | C24: =IF(C22=0,0,C23/C22) -> 0.60493893 | D24: =IF(D22=0,0,D23/D22) -> 0.48365208 | E24: =IF(E22=0,0,E23/E22) -> 0.56200607 | F24: =IF(F22=0,0,F23/F22) -> 0.60808345

Sheet 07_OpEx
A1: Operating Expenses
A3: Expense Category | B3: 2026 | C3: 2027 | D3: 2028 | E3: 2029 | F3: 2030
A5: Team & Salaries | B5: ='04_Assumptions'!B24 -> 100000 | C5: ='04_Assumptions'!C24 -> 300000 | D5: ='04_Assumptions'!D24 -> 400000 | E5: ='04_Assumptions'!E24 -> 500000 | F5: ='04_Assumptions'!F24 -> 600000
A6: R&D & Validation | B6: ='04_Assumptions'!B25 -> 50000 | C6: ='04_Assumptions'!C25 -> 100000 | D6: ='04_Assumptions'!D25 -> 80000 | E6: ='04_Assumptions'!E25 -> 60000 | F6: ='04_Assumptions'!F25 -> 50000
A7: Marketing & Sales | B7: ='04_Assumptions'!B26 -> 20000 | C7: ='04_Assumptions'!C26 -> 120000 | D7: ='04_Assumptions'!D26 -> 200000 | E7: ='04_Assumptions'!E26 -> 250000 | F7: ='04_Assumptions'!F26 -> 300000
A8: General & Admin | B8: ='04_Assumptions'!B27 -> 30000 | C8: ='04_Assumptions'!C27 -> 80000 | D8: ='04_Assumptions'!D27 -> 120000 | E8: ='04_Assumptions'!E27 -> 150000 | F8: ='04_Assumptions'!F27 -> 180000
A9: TOTAL OPEX (€) | B9: =SUM(B5:B8) -> 200000 | C9: =SUM(C5:C8) -> 600000 | D9: =SUM(D5:D8) -> 800000 | E9: =SUM(E5:E8) -> 960000 | F9: =SUM(F5:F8) -> 1130000

Sheet 08_P&L
A1: Profit & Loss Statement
A3: Line Item | B3: 2026 | C3: 2027 | D3: 2028 | E3: 2029 | F3: 2030
A5: Revenue | B5: ='05_Revenue_Model'!B62 -> 0 | C5: ='05_Revenue_Model'!C62 -> 61354 | D5: ='05_Revenue_Model'!D62 -> 839676.8 | E5: ='05_Revenue_Model'!E62 -> 3052923.9 | F5: ='05_Revenue_Model'!F62 -> 7023199.5
A6: COGS | B6: =-'06_COGS'!B20 -> 0 | C6: =-'06_COGS'!C20 -> -24238.577 | D6: =-'06_COGS'!D20 -> -433565.37 | E6: =-'06_COGS'!E20 -> -1337162.1 | F6: =-'06_COGS'!F20 -> -2752508.1
A7: Gross Profit | B7: =B5+B6 -> 0 | C7: =C5+C6 -> 37115.423 | D7: =D5+D6 -> 406111.43 | E7: =E5+E6 -> 1715761.8 | F7: =F5+F6 -> 4270691.4
A8: Gross Margin % | B8: =IF(B5=0,0,B7/B5) -> 0 | C8: =IF(C5=0,0,C7/C5) -> 0.60493893 | D8: =IF(D5=0,0,D7/D5) -> 0.48365208 | E8: =IF(E5=0,0,E7/E5) -> 0.56200607 | F8: =IF(F5=0,0,F7/F5) -> 0.60808345
A10: Operating Expenses
A11: Team & Salaries | B11: =-'04_Assumptions'!B24 -> -100000 | C11: =-'04_Assumptions'!C24 -> -300000 | D11: =-'04_Assumptions'!D24 -> -400000 | E11: =-'04_Assumptions'!E24 -> -500000 | F11: =-'04_Assumptions'!F24 -> -600000
A12: R&D & Validation | B12: =-'04_Assumptions'!B25 -> -50000 | C12: =-'04_Assumptions'!C25 -> -100000 | D12: =-'04_Assumptions'!D25 -> -80000 | E12: =-'04_Assumptions'!E25 -> -60000 | F12: =-'04_Assumptions'!F25 -> -50000
A13: Marketing & Sales | B13: =-'04_Assumptions'!B26 -> -20000 | C13: =-'04_Assumptions'!C26 -> -120000 | D13: =-'04_Assumptions'!D26 -> -200000 | E13: =-'04_Assumptions'!E26 -> -250000 | F13: =-'04_Assumptions'!F26 -> -300000
A14: General & Admin | B14: =-'04_Assumptions'!B27 -> -30000 | C14: =-'04_Assumptions'!C27 -> -80000 | D14: =-'04_Assumptions'!D27 -> -120000 | E14: =-'04_Assumptions'!E27 -> -150000 | F14: =-'04_Assumptions'!F27 -> -180000
A15: Total OpEx | B15: =SUM(B11:B14) -> -200000 | C15: =SUM(C11:C14) -> -600000 | D15: =SUM(D11:D14) -> -800000 | E15: =SUM(E11:E14) -> -960000 | F15: =SUM(F11:F14) -> -1130000
A17: EBITDA | B17: =B7+B15 -> -200000 | C17: =C7+C15 -> -562884.58 | D17: =D7+D15 -> -393888.57 | E17: =E7+E15 -> 755761.76 | F17: =F7+F15 -> 3140691.4
A18: EBITDA Margin % | B18: =IF(B5=0,0,B17/B5) -> 0 | C18: =IF(C5=0,0,C17/C5) -> -9.1743746 | D18: =IF(D5=0,0,D17/D5) -> -0.46909546 | E18: =IF(E5=0,0,E17/E5) -> 0.24755342 | F18: =IF(F5=0,0,F17/F5) -> 0.44718812

Sheet 09_Cash_Flow
A1: Cash Flow Statement
A3: Line Item | B3: 2026 | C3: 2027 | D3: 2028 | E3: 2029 | F3: 2030
A5: OPERATING ACTIVITIES
A6: EBITDA | B6: ='08_P&L'!B17 -> -200000 | C6: ='08_P&L'!C17 -> -562884.58 | D6: ='08_P&L'!D17 -> -393888.57 | E6: ='08_P&L'!E17 -> 755761.76 | F6: ='08_P&L'!F17 -> 3140691.4
A7: Change in Working Capital | B7: =-('08_P&L'!B5*60/365) -> 0 | C7: =-('08_P&L'!C5*60/365) -> -10085.589 | D7: =-('08_P&L'!D5*60/365) -> -138029.06 | E7: =-('08_P&L'!E5*60/365) -> -501850.5 | F7: =-('08_P&L'!F5*60/365) -> -1154498.6
A8: Operating Cash Flow | B8: =B6+B7 -> -200000 | C8: =C6+C7 -> -572970.17 | D8: =D6+D7 -> -531917.64 | E8: =E6+E7 -> 253911.26 | F8: =F6+F7 -> 1986192.9
A10: INVESTING ACTIVITIES
A11: CapEx | B11: 0 | C11: 0 | D11: 0 | E11: 0 | F11: 0
A13: FINANCING ACTIVITIES
A14: Equity Raised | B14: ='04_Assumptions'!B30 -> 200000 | C14: ='04_Assumptions'!C30 -> 1500000 | D14: ='04_Assumptions'!D30 -> 4000000 | E14: ='04_Assumptions'!E30 -> 0 | F14: ='04_Assumptions'!F30 -> 0
A16: NET CHANGE IN CASH | B16: =B8+B11+B14 -> 0 | C16: =C8+C11+C14 -> 927029.83 | D16: =D8+D11+D14 -> 3468082.4 | E16: =E8+E11+E14 -> 253911.26 | F16: =F8+F11+F14 -> 1986192.9
A18: Beginning Cash | B18: 0 | C18: =B19 -> 0 | D18: =C19 -> 927029.83 | E18: =D19 -> 4395112.2 | F18: =E19 -> 4649023.5
A19: Ending Cash | B19: =B18+B16 -> 0 | C19: =C18+C16 -> 927029.83 | D19: =D18+D16 -> 4395112.2 | E19: =E18+E16 -> 4649023.5 | F19: =F18+F16 -> 6635216.3

Sheet 10_KPIs
A1: Key Performance Indicators
A3: KPI | B3: 2026 | C3: 2027 | D3: 2028 | E3: 2029 | F3: 2030
A5: UNIT ECONOMICS
A6: Avg Revenue per Customer (€) | B6: =IF('05_Revenue_Model'!B30=0,0,'05_Revenue_Model'!B29/'05_Revenue_Model'!B30) -> 0 | C6: =IF('05_Revenue_Model'!C30=0,0,'05_Revenue_Model'!C29/'05_Revenue_Model'!C30) -> 618.4879 | D6: =IF('05_Revenue_Model'!D30=0,0,'05_Revenue_Model'!D29/'05_Revenue_Model'!D30) -> 807.09039 | E6: =IF('05_Revenue_Model'!E30=0,0,'05_Revenue_Model'!E29/'05_Revenue_Model'!E30) -> 975.92423 | F6: =IF('05_Revenue_Model'!F30=0,0,'05_Revenue_Model'!F29/'05_Revenue_Model'!F30) -> 1153.9714
A7: Avg COGS per Customer (€) | B7: =IF('05_Revenue_Model'!B30=0,0,'06_COGS'!B11/'05_Revenue_Model'!B30) -> 0 | C7: =IF('05_Revenue_Model'!C30=0,0,'06_COGS'!C11/'05_Revenue_Model'!C30) -> 125.10774 | D7: =IF('05_Revenue_Model'!D30=0,0,'06_COGS'!D11/'05_Revenue_Model'!D30) -> 142.95667 | E7: =IF('05_Revenue_Model'!E30=0,0,'06_COGS'!E11/'05_Revenue_Model'!E30) -> 182.29697 | F7: =IF('05_Revenue_Model'!F30=0,0,'06_COGS'!F11/'05_Revenue_Model'!F30) -> 224.34465
A8: Gross Profit per Customer (€) | B8: =B6-B7 -> 0 | C8: =C6-C7 -> 493.38016 | D8: =D6-D7 -> 664.13371 | E8: =E6-E7 -> 793.62726 | F8: =F6-F7 -> 929.62671
A10: CUSTOMER METRICS
A11: New Customers Acquired | B11: ='04_Assumptions'!B12+'04_Assumptions'!B13+'04_Assumptions'!B14 -> 10 | C11: ='04_Assumptions'!C12+'04_Assumptions'!C13+'04_Assumptions'!C14 -> 90 | D11: ='04_Assumptions'!D12+'04_Assumptions'!D13+'04_Assumptions'!D14 -> 440 | E11: ='04_Assumptions'!E12+'04_Assumptions'!E13+'04_Assumptions'!E14 -> 720 | F11: ='04_Assumptions'!F12+'04_Assumptions'!F13+'04_Assumptions'!F14 -> 950
A12: Customer Churn Count | B12: ='05_Revenue_Model'!B8+'05_Revenue_Model'!B16+'05_Revenue_Model'!B24 -> 0 | C12: ='05_Revenue_Model'!C8+'05_Revenue_Model'!C16+'05_Revenue_Model'!C24 -> 0.8 | D12: ='05_Revenue_Model'!D8+'05_Revenue_Model'!D16+'05_Revenue_Model'!D24 -> 9.92 | E12: ='05_Revenue_Model'!E8+'05_Revenue_Model'!E16+'05_Revenue_Model'!E24 -> 52.928 | F12: ='05_Revenue_Model'!F8+'05_Revenue_Model'!F16+'05_Revenue_Model'!F24 -> 143.56224
A13: Net Customer Addition | B13: =B11-B12 -> 10 | C13: =C11-C12 -> 89.2 | D13: =D11-D12 -> 430.08 | E13: =E11-E12 -> 667.072 | F13: =F11-F12 -> 806.43776
A14: Total Active Customers | B14: ='05_Revenue_Model'!B30 -> 10 | C14: ='05_Revenue_Model'!C30 -> 99.2 | D14: ='05_Revenue_Model'!D30 -> 529.28 | E14: ='05_Revenue_Model'!E30 -> 1196.352 | F14: ='05_Revenue_Model'!F30 -> 2002.7898
A16: EFFICIENCY METRICS
A17: Revenue per Kg (€) | B17: =IF('06_COGS'!B8=0,0,'05_Revenue_Model'!B29/'06_COGS'!B8) -> 0 | C17: =IF('06_COGS'!C8=0,0,'05_Revenue_Model'!C29/'06_COGS'!C8) -> 17.273086 | D17: =IF('06_COGS'!D8=0,0,'05_Revenue_Model'!D29/'06_COGS'!D8) -> 18.73977 | E17: =IF('06_COGS'!E8=0,0,'05_Revenue_Model'!E29/'06_COGS'!E8) -> 16.834571 | F17: =IF('06_COGS'!F8=0,0,'05_Revenue_Model'!F29/'06_COGS'!F8) -> 15.276404
A18: COGS per Kg (€) | B18: ='04_Assumptions'!B18 -> 3.494 | C18: ='04_Assumptions'!C18 -> 3.494 | D18: ='04_Assumptions'!D18 -> 3.3193 | E18: ='04_Assumptions'!E18 -> 3.1446 | F18: ='04_Assumptions'!F18 -> 2.9699
A19: Contribution Margin per Kg (€) | B19: =B17-B18 -> -3.494 | C19: =C17-C18 -> 13.779086 | D19: =D17-D18 -> 15.42047 | E19: =E17-E18 -> 13.689971 | F19: =F17-F18 -> 12.306504

Sheet 11_Funding
A1: Funding Rounds & Cap Table
A3: Round | B3: Year | C3: Amount Raised | D3: Pre-Money | E3: Post-Money | F3: Equity %
A4: Seed | B4: 2026 | C4: ='04_Assumptions'!B30 -> 200000 | D4: ='04_Assumptions'!B31 -> 2000000 | E4: =C4+D4 -> 2200000 | F4: =C4/E4 -> 0.090909091
A5: Pre-A | B5: 2027 | C5: ='04_Assumptions'!C30 -> 1500000 | D5: ='04_Assumptions'!C31 -> 7000000 | E5: =C5+D5 -> 8500000 | F5: =C5/E5 -> 0.17647059
A6: Series A | B6: 2028 | C6: ='04_Assumptions'!D30 -> 4000000 | D6: ='04_Assumptions'!D31 -> 14000000 | E6: =C6+D6 -> 18000000 | F6: =C6/E6 -> 0.22222222
A8: Cap Table Evolution (%)
A10: Stakeholder | B10: Post-Seed % | C10: Post-Pre-A % | D10: Post-Series A %
A11: Founders | B11: =1-F4 -> 0.90909091 | C11: =B11*(1-F5) -> 0.7486631 | D11: =C11*(1-F6) -> 0.58229352
A12: Seed Investors | B12: =F4 -> 0.090909091 | C12: =B12*(1-F5) -> 0.07486631 | D12: =C12*(1-F6) -> 0.058229352
A13: Pre-A Investors | B13: 0 | C13: =F5 -> 0.17647059 | D13: =C13*(1-F6) -> 0.1372549
A14: Series A Investors | B14: 0 | C14: 0 | D14: =F6 -> 0.22222222
A15: Total | B15: =SUM(B11:B13) -> 1 | C15: =SUM(C11:C13) -> 1 | D15: =SUM(D11:D14) -> 1
A17: Cap Table Evolution (€)
A19: Stakeholder | B19: Post-Seed % | C19: Post-Pre-A % | D19: Post-Series A %
A20: Founders | B20: =B11*$E$4 -> 2000000 | C20: =C11*$E$5 -> 6363636.4 | D20: =D11*$E$6 -> 10481283
A21: Seed Investors | B21: =B12*$E$4 -> 200000 | C21: =C12*$E$5 -> 636363.64 | D21: =D12*$E$6 -> 1048128.3
A22: Pre-A Investors | B22: =B13*$E$4 -> 0 | C22: =C13*$E$5 -> 1500000 | D22: =D13*$E$6 -> 2470588.2
A23: Series A Investors | B23: =B14*$E$4 -> 0 | C23: =C14*$E$5 -> 0 | D23: =D14*$E$6 -> 4000000
A24: Total | B24: =SUM(B20:B22) -> 2200000 | C24: =SUM(C20:C22) -> 8500000 | D24: =SUM(D20:D23) -> 18000000

Sheet 12_Scenarios
A1: Scenario Analysis
A2: Current model reflects BASE CASE scenario
A4: Scenario | B4: 2028 Revenue | C4: 2028 Customers | D4: Key Assumptions
A5: Conservative | B5: €1.2M - €1.5M | C5: 150-200 | D5: Slower partnership development, 20% lower pricing
A6: Base Case | B6: €1.8M - €2.5M | C6: 200-300 | D6: Current model assumptions
A7: Aggressive | B7: €3.5M - €5M | C7: 400-600 | D7: Faster partner network activation, regulatory fast-track
A9: Scenario Comparison - 5 Year Revenue
A10: Scenario | B10: 2026 | C10: 2027 | D10: 2028 | E10: 2029 | F10: 2030
A11: Conservative (€) | B11: 10000 | C11: 120000 | D11: 1200000 | E11: 2500000 | F11: 4500000
A12: Base Case (€) | B12: ='08_P&L'!B5 -> 0 | C12: ='08_P&L'!C5 -> 61354 | D12: ='08_P&L'!D5 -> 839676.8 | E12: ='08_P&L'!E5 -> 3052923.9 | F12: ='08_P&L'!F5 -> 7023199.5
A13: Aggressive (€) | B13: 15000 | C13: 300000 | D13: 4000000 | E13: 7500000 | F13: 12000000

Sheet 13_Sensitivity
A1: Sensitivity Analysis
A3: Key Driver | B3: Base Value | C3: -20% | D3: -10% | E3: Base | F3: +10% | G3: +20%
A5: 2028 Revenue Sensitivity
A6: Customer Acquisition | B6: ='04_Assumptions'!D12 -> 250 | C6: ='04_Assumptions'!D12*0.8 -> 200 | D6: ='04_Assumptions'!D12*0.9 -> 225 | E6: ='04_Assumptions'!D12*1 -> 250 | F6: ='04_Assumptions'!D12*1.1 -> 275 | G6: ='04_Assumptions'!D12*1.2 -> 300
A7: Impact on 2028 Revenue (€) | C7: ='08_P&L'!D5*0.8 -> 671741.44 | D7: ='08_P&L'!D5*0.9 -> 755709.12 | E7: ='08_P&L'!D5*1 -> 839676.8 | F7: ='08_P&L'!D5*1.1 -> 923644.48 | G7: ='08_P&L'!D5*1.2 -> 1007612.2
A9: Pricing | B9: ='04_Assumptions'!D7 -> 800 | C9: ='04_Assumptions'!D7*0.8 -> 640 | D9: ='04_Assumptions'!D7*0.9 -> 720 | E9: ='04_Assumptions'!D7*1 -> 800 | F9: ='04_Assumptions'!D7*1.1 -> 880 | G9: ='04_Assumptions'!D7*1.2 -> 960
A10: Impact on 2028 Revenue (€) | C10: ='08_P&L'!D5*0.8 -> 671741.44 | D10: ='08_P&L'!D5*0.9 -> 755709.12 | E10: ='08_P&L'!D5*1 -> 839676.8 | F10: ='08_P&L'!D5*1.1 -> 923644.48 | G10: ='08_P&L'!D5*1.2 -> 1007612.2
A12: COGS per kg | B12: ='04_Assumptions'!D16 -> 0 | C12: ='04_Assumptions'!D16*0.8 -> 0 | D12: ='04_Assumptions'!D16*0.9 -> 0 | E12: ='04_Assumptions'!D16*1 -> 0 | F12: ='04_Assumptions'!D16*1.1 -> 0 | G12: ='04_Assumptions'!D16*1.2 -> 0
A13: Impact on 2028 Gross Margin % | C13: ='08_P&L'!D8*1.2 -> 0.58038249 | D13: ='08_P&L'!D8*1.1 -> 0.53201728 | E13: ='08_P&L'!D8*1 -> 0.48365208 | F13: ='08_P&L'!D8*0.899999999999999 -> 0.43528687 | G13: ='08_P&L'!D8*0.8 -> 0.38692166

Sheet 14_Unit_Costs_BOM
A1: ReSemis - Unit Costs & Bill of Materials (BOM)
A2: Source: BOOK_RESEMIS_business_plus_financials.pdf - Sezione 4.4
A4: STRATO ESTERNO (Outer Coating)
A5: Ingrediente | B5: % | C5: €/kg ingrediente | D5: €/kg prodotto | E5: Funzione | F5: Fonte
A6: Alginato di sodio | B6: 0.015 | C6: 10 | D6: =B6*C6 -> 0.15 | E6: Film protettivo idrogel | F6: Fornitori chimici industriali
A7: Cloruro di calcio | B7: 0.02 | C7: 1 | D7: =B7*C7 -> 0.02 | E7: Reticolante per gelificazione | F7: Chimica industriale, agraria
A8: Gomma di guar | B8: 0.015 | C8: 8 | D8: =B8*C8 -> 0.12 | E8: Rinforzo strutturale e resistenza digestiva | F8: Amazon bulk, Tecnosur
A9: Chitosano (opzionale) | B9: 0.005 | C9: 60 | D9: =B9*C9 -> 0.3 | E9: Azione antimicrobica naturale | F9: Fornitori biotech
A10: L. plantarum | B10: 0.008 | C10: 20 | D10: =B10*C10 -> 0.16 | E10: Controllo patogeni, miglioramento intestinale | F10: Sacco System, Kerry
A11: L. reuteri | B11: 0.002 | C11: 40 | D11: =B11*C11 -> 0.08 | E11: Produzione reuterina, equilibrio intestinale | F11: Fornitori fermenti
A12: Inulina + FOS | B12: 0.005 | C12: 5 | D12: =B12*C12 -> 0.025 | E12: Prebiotici per supporto microbiota | F12: Erboristerie, Europlants
A13: Sodio citrato | B13: 0.003 | C13: 3 | D13: =B13*C13 -> 0.009 | E13: Stabilizzatore pH e regolatore solubilità | F13: Chimica alimentare
A14: Enzimi digestivi | B14: 0.005 | C14: 30 | D14: =B14*C14 -> 0.15 | E14: Attivazione post-espulsione | F14: Novozymes, zootecnia
A15: Tannini/polifenoli | B15: 0.003 | C15: 15 | D15: =B15*C15 -> 0.045 | E15: Azione antiossidante e antimicrobica | F15: Fitoterapia, Acacia
A17: STRATO INTERNO (Inner Coating)
A18: Ingrediente | B18: % | C18: €/kg ingrediente | D18: €/kg prodotto | E18: Funzione | F18: Fonte
A19: Pectina | B19: 0.015 | C19: 15 | D19: =B19*C19 -> 0.225 | E19: Addensante da agrumi | F19: Farmalabor, alimentare
A20: B. subtilis | B20: 0.015 | C20: 20 | D20: =B20*C20 -> 0.3 | E20: Batterio utile | F20: Microrganismi tecnici
A21: T. harzianum | B21: 0.005 | C21: 25 | D21: =B21*C21 -> 0.125 | E21: Fungo stimolatore | F21: AgriBio, Biogard
A22: Argilla bentonite | B22: 0.01 | C22: 0.5 | D22: =B22*C22 -> 0.005 | E22: Protezione fisica | F22: Agraria, fornitori
A23: Biochar attivato | B23: 0.01 | C23: 2 | D23: =B23*C23 -> 0.02 | E23: Migliora ritenzione | F23: Biochar locali
A24: Alghe marine | B24: 0.01 | C24: 10 | D24: =B24*C24 -> 0.1 | E24: Stimolatore naturale | F24: AlgaPlas, Seasol
A25: Peptidi | B25: 0.002 | C25: 80 | D25: =B25*C25 -> 0.16 | E25: Nutrimento | F25: Biotech
A27: TOTALE MATERIE PRIME | B27: =SUM(B6:B15,B19:B25) -> 0.148 | D27: =SUM(D6:D15,D19:D25) -> 1.994
A29: COSTI INDUSTRIALI E GENERALI (per kg)
A30: Voce | D30: €/kg | E30: Note
A31: Lavorazione (miscelazione, gelificazione, essiccazione) | D31: 0.6 | E31: Conto terzi / toll manufacturing
A32: Packaging e logistica | D32: 0.3 | E32: Film barriera, formati 5-10-25 kg
A33: Controllo qualità | D33: 0.2 | E33: QA/QC, CoA, tracciabilità lotti
A34: Ammortamento impianto e costi generali | D34: 0.4 | E34: Overhead produzione
A35: TOTALE COSTI INDUSTRIALI | D35: =SUM(D31:D34) -> 1.5
A37: COSTO TOTALE DI PRODUZIONE | D37: =D27+D35 -> 3.494
A38: Costo senza opzionali (chitosano) | D38: =D37-D9 -> 3.194
A40: PREZZI DI VENDITA PER SEGMENTO
A41: Segmento | B41: Prezzo €/kg | C41: Costo €/kg | D41: Margine €/kg | E41: Margine %
A42: Allevamenti (polli, suini, ruminanti) | B42: 9 | C42: =$D$37 -> 3.494 | D42: =B42-C42 -> 5.506 | E42: =D42/B42 -> 0.61177778
A43: Pet Care (cani, gatti) | B43: 17 | C43: =$D$37 -> 3.494 | D43: =B43-C43 -> 13.506 | E43: =D43/B43 -> 0.79447059
A44: Agricolo / Riforestazione | B44: 11 | C44: =$D$37 -> 3.494 | D44: =B44-C44 -> 7.506 | E44: =D44/B44 -> 0.68236364
A45: Ittico (acquacoltura) | B45: 10 | C45: =$D$37 -> 3.494 | D45: =B45-C45 -> 6.506 | E45: =D45/B45 -> 0.6506

Sheet 15_OpEx_Budget_Detail
A1: ReSemis - Budget Dettagliato per Fase
A2: Source: BOOK_RESEMIS + Roadmap documents
A4: FASE 1 - R&D & Validazione (2026)
A5: Budget: €200.000 (Seed Round)
A6: Categoria | B6: Gen | C6: Feb | D6: Mar | E6: Apr | F6: Mag | G6: Giu | H6: Lug | I6: Ago | J6: Set | K6: Ott | L6: Nov | M6: Dic | N6: TOTALE
A7: Sphera (encapsulation lab) | B7: 8000 | C7: 8000 | D7: 5000 | E7: 5000 | F7: 5000 | G7: 5000 | H7: 4000 | I7: 3000 | J7: 3000 | K7: 2000 | L7: 1000 | M7: 1000 | N7: =SUM(B7:M7) -> 50000
A8: Brevetto & IP (PCT) | B8: 1000 | C8: 1000 | D8: 1000 | E8: 1000 | F8: 1000 | G8: 1000 | H8: 1000 | I8: 1000 | J8: 1000 | K8: 1000 | L8: 0 | M8: 0 | N8: =SUM(B8:M8) -> 10000
A9: Team (founders + consulenze) | B9: 5500 | C9: 5500 | D9: 5500 | E9: 5500 | F9: 5500 | G9: 5500 | H9: 5500 | I9: 5500 | J9: 5500 | K9: 5500 | L9: 5000 | M9: 5000 | N9: =SUM(B9:M9) -> 65000
A10: Affitto/Hub Light | B10: 500 | C10: 500 | D10: 500 | E10: 500 | F10: 1000 | G10: 1000 | H10: 1000 | I10: 1000 | J10: 500 | K10: 500 | L10: 500 | M10: 500 | N10: =SUM(B10:M10) -> 8000
A11: Ufficio/attrezzi/test campo | B11: 3000 | C11: 3000 | D11: 3000 | E11: 3000 | F11: 3000 | G11: 3000 | H11: 2000 | I11: 2000 | J11: 2000 | K11: 2000 | L11: 2000 | M11: 2000 | N11: =SUM(B11:M11) -> 30000
A12: Admin & contabilità | B12: 400 | C12: 400 | D12: 400 | E12: 400 | F12: 400 | G12: 400 | H12: 400 | I12: 400 | J12: 400 | K12: 500 | L12: 500 | M12: 400 | N12: =SUM(B12:M12) -> 5000
A13: Buffer & imprevisti | B13: 2000 | C13: 2000 | D13: 1000 | E13: 1000 | F13: 500 | G13: 500 | H13: 500 | I13: 500 | J13: 500 | K13: 500 | L13: 500 | M13: 500 | N13: =SUM(B13:M13) -> 10000
A14: TOTALE FASE 1 | B14: =SUM(B7:B13) -> 20400 | C14: =SUM(C7:C13) -> 20400 | D14: =SUM(D7:D13) -> 16400 | E14: =SUM(E7:E13) -> 16400 | F14: =SUM(F7:F13) -> 16400 | G14: =SUM(G7:G13) -> 16400 | H14: =SUM(H7:H13) -> 14400 | I14: =SUM(I7:I13) -> 13400 | ... N14: =SUM(N7:N13) -> 178000
A16: FASE 2 - Pre-industrializzazione (2027)
A17: Budget: €1.500.000 (Pre-A Round)
A18: Categoria | B18: Gen | C18: Feb | D18: Mar | E18: Apr | F18: Mag | G18: Giu | H18: Lug | I18: Ago | J18: Set | K18: Ott | L18: Nov | M18: Dic | N18: TOTALE
A19: Produzione (impianti pilota) | B19: 40000 | C19: 45000 | D19: 50000 | E19: 50000 | F19: 55000 | G19: 55000 | H19: 50000 | I19: 50000 | J19: 55000 | K19: 55000 | L19: 50000 | M19: 45000 | N19: =SUM(B19:M19) -> 600000
A20: Capitale circolante | B20: 20000 | C20: 20000 | D20: 25000 | E20: 25000 | F20: 25000 | G20: 25000 | H20: 30000 | I20: 30000 | J20: 25000 | K20: 25000 | L20: 25000 | M20: 25000 | N20: =SUM(B20:M20) -> 300000
A21: Team (vendite + ops) | B21: 22000 | C21: 22000 | D21: 25000 | E21: 25000 | F21: 25000 | G21: 25000 | H21: 28000 | I21: 28000 | J21: 25000 | K21: 25000 | L21: 25000 | M21: 25000 | N21: =SUM(B21:M21) -> 300000
A22: Regolatorio & validazioni | B22: 10000 | C22: 10000 | D22: 12000 | E22: 15000 | F22: 15000 | G22: 15000 | H22: 12000 | I22: 12000 | J22: 12000 | K22: 12000 | L22: 12000 | M22: 13000 | N22: =SUM(B22:M22) -> 150000
A23: IP (PCT/national phase) | B23: 6000 | C23: 6000 | D23: 6000 | E23: 6000 | F23: 7000 | G23: 7000 | H23: 7000 | I23: 6000 | J23: 6000 | K23: 6000 | L23: 6000 | M23: 6000 | N23: =SUM(B23:M23) -> 75000
A24: Contingenze | B24: 5000 | C24: 5000 | D24: 5000 | E24: 6000 | F24: 6000 | G24: 6000 | H24: 7000 | I24: 7000 | J24: 7000 | K24: 7000 | L24: 7000 | M24: 7000 | N24: =SUM(B24:M24) -> 75000
A25: TOTALE FASE 2 | B25: =SUM(B19:B24) -> 103000 | C25: =SUM(C19:C24) -> 108000 | D25: =SUM(D19:D24) -> 123000 | E25: =SUM(E19:E24) -> 127000 | F25: =SUM(F19:F24) -> 133000 | G25: =SUM(G19:G24) -> 133000 | H25: =SUM(H19:H24) -> 134000 | I25: =SUM(I19:I24) -> 133000 | ... N25: =SUM(N19:N24) -> 1500000
A27: FASE 3 - Go-to-Market (2028)
A28: Budget: €4.000.000 (Series A Round)
A29: Categoria | B29: Gen | C29: Feb | D29: Mar | E29: Apr | F29: Mag | G29: Giu | H29: Lug | I29: Ago | J29: Set | K29: Ott | L29: Nov | M29: Dic | N29: TOTALE
A30: Capacity & CapEx/linea Valdarno | B30: 90000 | C30: 95000 | D30: 100000 | E30: 100000 | F30: 105000 | G30: 105000 | H30: 100000 | I30: 100000 | J30: 105000 | K30: 100000 | L30: 100000 | M30: 100000 | N30: =SUM(B30:M30) -> 1200000
A31: Working capital | B31: 55000 | C31: 60000 | D31: 65000 | E31: 65000 | F31: 65000 | G31: 65000 | H31: 60000 | I31: 60000 | J31: 65000 | K31: 65000 | L31: 60000 | M31: 65000 | N31: =SUM(B31:M31) -> 750000
A32: Team commerciale & field | B32: 35000 | C32: 35000 | D32: 38000 | E32: 38000 | F32: 40000 | G32: 40000 | H32: 40000 | I32: 40000 | J32: 38000 | K32: 38000 | L32: 38000 | M32: 40000 | N32: =SUM(B32:M32) -> 460000
A33: Marketing & GTM | B33: 22000 | C33: 25000 | D33: 28000 | E33: 28000 | F33: 28000 | G33: 28000 | H33: 25000 | I33: 22000 | J33: 25000 | K33: 25000 | L33: 22000 | M33: 22000 | N33: =SUM(B33:M33) -> 300000
A34: Qualità/regolatorio (FPR/CE) | B34: 12000 | C34: 12000 | D34: 13000 | E34: 13000 | F34: 13000 | G34: 13000 | H34: 12000 | I34: 12000 | J34: 12000 | K34: 12000 | L34: 13000 | M34: 12000 | N34: =SUM(B34:M34) -> 149000
A35: Contingenze & hedging | B35: 12000 | C35: 12000 | D35: 12000 | E35: 13000 | F35: 13000 | G35: 13000 | H35: 12000 | I35: 12000 | J35: 13000 | K35: 13000 | L35: 12000 | M35: 13000 | N35: =SUM(B35:M35) -> 150000
A36: TOTALE FASE 3 | B36: =SUM(B30:B35) -> 226000 | C36: =SUM(C30:C35) -> 239000 | D36: =SUM(D30:D35) -> 256000 | E36: =SUM(E30:E35) -> 257000 | F36: =SUM(F30:F35) -> 264000 | G36: =SUM(G30:G35) -> 264000 | H36: =SUM(H30:H35) -> 249000 | I36: =SUM(I30:I35) -> 246000 | ... N36: =SUM(N30:N35) -> 3009000
A38: RIEPILOGO BUDGET PER FASE
A39: Fase | B39: Anno | C39: Budget Totale | D39: Funding Round | E39: % Use of Funds
A40: Fase 1 - R&D | B40: 2026 | C40: =N14 -> 178000 | D40: Seed (€200k) | E40: =C40/200000 -> 0.89
A41: Fase 2 - Pre-industria | B41: 2027 | C41: =N25 -> 1500000 | D41: Pre-A (€1.5M) | E41: =C41/1500000 -> 1
A42: Fase 3 - GTM | B42: 2028 | C42: =N36 -> 3009000 | D42: Series A (€4M) | E42: =C42/4000000 -> 0.75225
A43: TOTALE 3 ANNI | C43: =SUM(C40:C42) -> 4687000
A45: CONFRONTO CON SCHEDA 07_OpEx
...

Sheet 16_Valuation_Models

Sheet 17_Dashboard
